2025-07-24 21:16:52,441 WARNING: PyNaCl is not installed, voice will NOT be supported
2025-07-24 21:18:54,018 WARNING: PyNaCl is not installed, voice will NOT be supported
2025-07-24 21:40:32,563 WARNING: PyNaCl is not installed, voice will NOT be supported
2025-07-24 21:40:32,565 INFO: logging in using static token
2025-07-24 21:40:35,256 INFO: Shard ID None has connected to Gateway (Session ID: a36b1f21221dfc3c636819ee7ddf7601).
2025-07-24 21:40:37,258 INFO: Bot started and ready.
2025-07-24 21:53:44,702 INFO: Shard ID None has successfully RESUMED session a36b1f21221dfc3c636819ee7ddf7601.
2025-07-24 21:58:34,520 INFO: Shard ID None has successfully RESUMED session a36b1f21221dfc3c636819ee7ddf7601.
2025-07-24 22:17:36,816 WARNING: PyNaCl is not installed, voice will NOT be supported
2025-07-24 22:17:36,817 INFO: logging in using static token
2025-07-24 22:17:39,893 INFO: Shard ID None has connected to Gateway (Session ID: 16acb5885c41db4aad25ac8e988a7b62).
2025-07-24 22:17:41,896 INFO: Bot started and ready.
2025-07-24 22:24:19,676 ERROR: Attempting a reconnect in 0.45s
Traceback (most recent call last):
  File "/Users/MuhammadUsman/anaconda3/lib/python3.10/site-packages/aiohttp/connector.py", line 1512, in _create_direct_connection
    hosts = await self._resolve_host(host, port, traces=traces)
  File "/Users/MuhammadUsman/anaconda3/lib/python3.10/site-packages/aiohttp/connector.py", line 1128, in _resolve_host
    return await asyncio.shield(resolved_host_task)
  File "/Users/MuhammadUsman/anaconda3/lib/python3.10/site-packages/aiohttp/connector.py", line 1159, in _resolve_host_with_throttle
    addrs = await self._resolver.resolve(host, port, family=self._family)
  File "/Users/MuhammadUsman/anaconda3/lib/python3.10/site-packages/aiohttp/resolver.py", line 40, in resolve
    infos = await self._loop.getaddrinfo(
  File "/Users/MuhammadUsman/anaconda3/lib/python3.10/asyncio/base_events.py", line 863, in getaddrinfo
    return await self.run_in_executor(
  File "/Users/MuhammadUsman/anaconda3/lib/python3.10/concurrent/futures/thread.py", line 58, in run
    result = self.fn(*self.args, **self.kwargs)
  File "/Users/MuhammadUsman/anaconda3/lib/python3.10/socket.py", line 955, in getaddrinfo
    for res in _socket.getaddrinfo(host, port, family, type, proto, flags):
socket.gaierror: [Errno 8] nodename nor servname provided, or not known

The above exception was the direct cause of the following exception:

Traceback (most recent call last):
  File "/Users/MuhammadUsman/anaconda3/lib/python3.10/site-packages/discord/client.py", line 701, in connect
    self.ws = await asyncio.wait_for(coro, timeout=60.0)
  File "/Users/MuhammadUsman/anaconda3/lib/python3.10/asyncio/tasks.py", line 445, in wait_for
    return fut.result()
  File "/Users/MuhammadUsman/anaconda3/lib/python3.10/site-packages/discord/gateway.py", line 375, in from_client
    socket = await client.http.ws_connect(str(url))
  File "/Users/MuhammadUsman/anaconda3/lib/python3.10/site-packages/discord/http.py", line 554, in ws_connect
    return await self.__session.ws_connect(url, **kwargs)
  File "/Users/MuhammadUsman/anaconda3/lib/python3.10/site-packages/aiohttp/client.py", line 1061, in _ws_connect
    resp = await self.request(
  File "/Users/MuhammadUsman/anaconda3/lib/python3.10/site-packages/aiohttp/client.py", line 770, in _request
    resp = await handler(req)
  File "/Users/MuhammadUsman/anaconda3/lib/python3.10/site-packages/aiohttp/client.py", line 725, in _connect_and_send_request
    conn = await self._connector.connect(
  File "/Users/MuhammadUsman/anaconda3/lib/python3.10/site-packages/aiohttp/connector.py", line 622, in connect
    proto = await self._create_connection(req, traces, timeout)
  File "/Users/MuhammadUsman/anaconda3/lib/python3.10/site-packages/aiohttp/connector.py", line 1189, in _create_connection
    _, proto = await self._create_direct_connection(req, traces, timeout)
  File "/Users/MuhammadUsman/anaconda3/lib/python3.10/site-packages/aiohttp/connector.py", line 1518, in _create_direct_connection
    raise ClientConnectorDNSError(req.connection_key, exc) from exc
aiohttp.client_exceptions.ClientConnectorDNSError: Cannot connect to host gateway-us-east1-b.discord.gg:443 ssl:default [nodename nor servname provided, or not known]
2025-07-24 22:24:20,168 ERROR: Attempting a reconnect in 1.97s
Traceback (most recent call last):
  File "/Users/MuhammadUsman/anaconda3/lib/python3.10/site-packages/aiohttp/connector.py", line 1512, in _create_direct_connection
    hosts = await self._resolve_host(host, port, traces=traces)
  File "/Users/MuhammadUsman/anaconda3/lib/python3.10/site-packages/aiohttp/connector.py", line 1128, in _resolve_host
    return await asyncio.shield(resolved_host_task)
  File "/Users/MuhammadUsman/anaconda3/lib/python3.10/site-packages/aiohttp/connector.py", line 1159, in _resolve_host_with_throttle
    addrs = await self._resolver.resolve(host, port, family=self._family)
  File "/Users/MuhammadUsman/anaconda3/lib/python3.10/site-packages/aiohttp/resolver.py", line 40, in resolve
    infos = await self._loop.getaddrinfo(
  File "/Users/MuhammadUsman/anaconda3/lib/python3.10/asyncio/base_events.py", line 863, in getaddrinfo
    return await self.run_in_executor(
  File "/Users/MuhammadUsman/anaconda3/lib/python3.10/concurrent/futures/thread.py", line 58, in run
    result = self.fn(*self.args, **self.kwargs)
  File "/Users/MuhammadUsman/anaconda3/lib/python3.10/socket.py", line 955, in getaddrinfo
    for res in _socket.getaddrinfo(host, port, family, type, proto, flags):
socket.gaierror: [Errno 8] nodename nor servname provided, or not known

The above exception was the direct cause of the following exception:

Traceback (most recent call last):
  File "/Users/MuhammadUsman/anaconda3/lib/python3.10/site-packages/discord/client.py", line 701, in connect
    self.ws = await asyncio.wait_for(coro, timeout=60.0)
  File "/Users/MuhammadUsman/anaconda3/lib/python3.10/asyncio/tasks.py", line 445, in wait_for
    return fut.result()
  File "/Users/MuhammadUsman/anaconda3/lib/python3.10/site-packages/discord/gateway.py", line 375, in from_client
    socket = await client.http.ws_connect(str(url))
  File "/Users/MuhammadUsman/anaconda3/lib/python3.10/site-packages/discord/http.py", line 554, in ws_connect
    return await self.__session.ws_connect(url, **kwargs)
  File "/Users/MuhammadUsman/anaconda3/lib/python3.10/site-packages/aiohttp/client.py", line 1061, in _ws_connect
    resp = await self.request(
  File "/Users/MuhammadUsman/anaconda3/lib/python3.10/site-packages/aiohttp/client.py", line 770, in _request
    resp = await handler(req)
  File "/Users/MuhammadUsman/anaconda3/lib/python3.10/site-packages/aiohttp/client.py", line 725, in _connect_and_send_request
    conn = await self._connector.connect(
  File "/Users/MuhammadUsman/anaconda3/lib/python3.10/site-packages/aiohttp/connector.py", line 622, in connect
    proto = await self._create_connection(req, traces, timeout)
  File "/Users/MuhammadUsman/anaconda3/lib/python3.10/site-packages/aiohttp/connector.py", line 1189, in _create_connection
    _, proto = await self._create_direct_connection(req, traces, timeout)
  File "/Users/MuhammadUsman/anaconda3/lib/python3.10/site-packages/aiohttp/connector.py", line 1518, in _create_direct_connection
    raise ClientConnectorDNSError(req.connection_key, exc) from exc
aiohttp.client_exceptions.ClientConnectorDNSError: Cannot connect to host gateway-us-east1-b.discord.gg:443 ssl:default [nodename nor servname provided, or not known]
2025-07-24 22:24:22,142 ERROR: Attempting a reconnect in 1.70s
Traceback (most recent call last):
  File "/Users/MuhammadUsman/anaconda3/lib/python3.10/site-packages/aiohttp/connector.py", line 1512, in _create_direct_connection
    hosts = await self._resolve_host(host, port, traces=traces)
  File "/Users/MuhammadUsman/anaconda3/lib/python3.10/site-packages/aiohttp/connector.py", line 1128, in _resolve_host
    return await asyncio.shield(resolved_host_task)
  File "/Users/MuhammadUsman/anaconda3/lib/python3.10/site-packages/aiohttp/connector.py", line 1159, in _resolve_host_with_throttle
    addrs = await self._resolver.resolve(host, port, family=self._family)
  File "/Users/MuhammadUsman/anaconda3/lib/python3.10/site-packages/aiohttp/resolver.py", line 40, in resolve
    infos = await self._loop.getaddrinfo(
  File "/Users/MuhammadUsman/anaconda3/lib/python3.10/asyncio/base_events.py", line 863, in getaddrinfo
    return await self.run_in_executor(
  File "/Users/MuhammadUsman/anaconda3/lib/python3.10/concurrent/futures/thread.py", line 58, in run
    result = self.fn(*self.args, **self.kwargs)
  File "/Users/MuhammadUsman/anaconda3/lib/python3.10/socket.py", line 955, in getaddrinfo
    for res in _socket.getaddrinfo(host, port, family, type, proto, flags):
socket.gaierror: [Errno 8] nodename nor servname provided, or not known

The above exception was the direct cause of the following exception:

Traceback (most recent call last):
  File "/Users/MuhammadUsman/anaconda3/lib/python3.10/site-packages/discord/client.py", line 701, in connect
    self.ws = await asyncio.wait_for(coro, timeout=60.0)
  File "/Users/MuhammadUsman/anaconda3/lib/python3.10/asyncio/tasks.py", line 445, in wait_for
    return fut.result()
  File "/Users/MuhammadUsman/anaconda3/lib/python3.10/site-packages/discord/gateway.py", line 375, in from_client
    socket = await client.http.ws_connect(str(url))
  File "/Users/MuhammadUsman/anaconda3/lib/python3.10/site-packages/discord/http.py", line 554, in ws_connect
    return await self.__session.ws_connect(url, **kwargs)
  File "/Users/MuhammadUsman/anaconda3/lib/python3.10/site-packages/aiohttp/client.py", line 1061, in _ws_connect
    resp = await self.request(
  File "/Users/MuhammadUsman/anaconda3/lib/python3.10/site-packages/aiohttp/client.py", line 770, in _request
    resp = await handler(req)
  File "/Users/MuhammadUsman/anaconda3/lib/python3.10/site-packages/aiohttp/client.py", line 725, in _connect_and_send_request
    conn = await self._connector.connect(
  File "/Users/MuhammadUsman/anaconda3/lib/python3.10/site-packages/aiohttp/connector.py", line 622, in connect
    proto = await self._create_connection(req, traces, timeout)
  File "/Users/MuhammadUsman/anaconda3/lib/python3.10/site-packages/aiohttp/connector.py", line 1189, in _create_connection
    _, proto = await self._create_direct_connection(req, traces, timeout)
  File "/Users/MuhammadUsman/anaconda3/lib/python3.10/site-packages/aiohttp/connector.py", line 1518, in _create_direct_connection
    raise ClientConnectorDNSError(req.connection_key, exc) from exc
aiohttp.client_exceptions.ClientConnectorDNSError: Cannot connect to host gateway-us-east1-b.discord.gg:443 ssl:default [nodename nor servname provided, or not known]
2025-07-24 22:24:23,852 ERROR: Attempting a reconnect in 8.27s
Traceback (most recent call last):
  File "/Users/MuhammadUsman/anaconda3/lib/python3.10/site-packages/aiohttp/connector.py", line 1512, in _create_direct_connection
    hosts = await self._resolve_host(host, port, traces=traces)
  File "/Users/MuhammadUsman/anaconda3/lib/python3.10/site-packages/aiohttp/connector.py", line 1128, in _resolve_host
    return await asyncio.shield(resolved_host_task)
  File "/Users/MuhammadUsman/anaconda3/lib/python3.10/site-packages/aiohttp/connector.py", line 1159, in _resolve_host_with_throttle
    addrs = await self._resolver.resolve(host, port, family=self._family)
  File "/Users/MuhammadUsman/anaconda3/lib/python3.10/site-packages/aiohttp/resolver.py", line 40, in resolve
    infos = await self._loop.getaddrinfo(
  File "/Users/MuhammadUsman/anaconda3/lib/python3.10/asyncio/base_events.py", line 863, in getaddrinfo
    return await self.run_in_executor(
  File "/Users/MuhammadUsman/anaconda3/lib/python3.10/concurrent/futures/thread.py", line 58, in run
    result = self.fn(*self.args, **self.kwargs)
  File "/Users/MuhammadUsman/anaconda3/lib/python3.10/socket.py", line 955, in getaddrinfo
    for res in _socket.getaddrinfo(host, port, family, type, proto, flags):
socket.gaierror: [Errno 8] nodename nor servname provided, or not known

The above exception was the direct cause of the following exception:

Traceback (most recent call last):
  File "/Users/MuhammadUsman/anaconda3/lib/python3.10/site-packages/discord/client.py", line 701, in connect
    self.ws = await asyncio.wait_for(coro, timeout=60.0)
  File "/Users/MuhammadUsman/anaconda3/lib/python3.10/asyncio/tasks.py", line 445, in wait_for
    return fut.result()
  File "/Users/MuhammadUsman/anaconda3/lib/python3.10/site-packages/discord/gateway.py", line 375, in from_client
    socket = await client.http.ws_connect(str(url))
  File "/Users/MuhammadUsman/anaconda3/lib/python3.10/site-packages/discord/http.py", line 554, in ws_connect
    return await self.__session.ws_connect(url, **kwargs)
  File "/Users/MuhammadUsman/anaconda3/lib/python3.10/site-packages/aiohttp/client.py", line 1061, in _ws_connect
    resp = await self.request(
  File "/Users/MuhammadUsman/anaconda3/lib/python3.10/site-packages/aiohttp/client.py", line 770, in _request
    resp = await handler(req)
  File "/Users/MuhammadUsman/anaconda3/lib/python3.10/site-packages/aiohttp/client.py", line 725, in _connect_and_send_request
    conn = await self._connector.connect(
  File "/Users/MuhammadUsman/anaconda3/lib/python3.10/site-packages/aiohttp/connector.py", line 622, in connect
    proto = await self._create_connection(req, traces, timeout)
  File "/Users/MuhammadUsman/anaconda3/lib/python3.10/site-packages/aiohttp/connector.py", line 1189, in _create_connection
    _, proto = await self._create_direct_connection(req, traces, timeout)
  File "/Users/MuhammadUsman/anaconda3/lib/python3.10/site-packages/aiohttp/connector.py", line 1518, in _create_direct_connection
    raise ClientConnectorDNSError(req.connection_key, exc) from exc
aiohttp.client_exceptions.ClientConnectorDNSError: Cannot connect to host gateway-us-east1-b.discord.gg:443 ssl:default [nodename nor servname provided, or not known]
2025-07-24 22:24:32,129 ERROR: Attempting a reconnect in 20.31s
Traceback (most recent call last):
  File "/Users/MuhammadUsman/anaconda3/lib/python3.10/site-packages/aiohttp/connector.py", line 1512, in _create_direct_connection
    hosts = await self._resolve_host(host, port, traces=traces)
  File "/Users/MuhammadUsman/anaconda3/lib/python3.10/site-packages/aiohttp/connector.py", line 1128, in _resolve_host
    return await asyncio.shield(resolved_host_task)
  File "/Users/MuhammadUsman/anaconda3/lib/python3.10/site-packages/aiohttp/connector.py", line 1159, in _resolve_host_with_throttle
    addrs = await self._resolver.resolve(host, port, family=self._family)
  File "/Users/MuhammadUsman/anaconda3/lib/python3.10/site-packages/aiohttp/resolver.py", line 40, in resolve
    infos = await self._loop.getaddrinfo(
  File "/Users/MuhammadUsman/anaconda3/lib/python3.10/asyncio/base_events.py", line 863, in getaddrinfo
    return await self.run_in_executor(
  File "/Users/MuhammadUsman/anaconda3/lib/python3.10/concurrent/futures/thread.py", line 58, in run
    result = self.fn(*self.args, **self.kwargs)
  File "/Users/MuhammadUsman/anaconda3/lib/python3.10/socket.py", line 955, in getaddrinfo
    for res in _socket.getaddrinfo(host, port, family, type, proto, flags):
socket.gaierror: [Errno 8] nodename nor servname provided, or not known

The above exception was the direct cause of the following exception:

Traceback (most recent call last):
  File "/Users/MuhammadUsman/anaconda3/lib/python3.10/site-packages/discord/client.py", line 701, in connect
    self.ws = await asyncio.wait_for(coro, timeout=60.0)
  File "/Users/MuhammadUsman/anaconda3/lib/python3.10/asyncio/tasks.py", line 445, in wait_for
    return fut.result()
  File "/Users/MuhammadUsman/anaconda3/lib/python3.10/site-packages/discord/gateway.py", line 375, in from_client
    socket = await client.http.ws_connect(str(url))
  File "/Users/MuhammadUsman/anaconda3/lib/python3.10/site-packages/discord/http.py", line 554, in ws_connect
    return await self.__session.ws_connect(url, **kwargs)
  File "/Users/MuhammadUsman/anaconda3/lib/python3.10/site-packages/aiohttp/client.py", line 1061, in _ws_connect
    resp = await self.request(
  File "/Users/MuhammadUsman/anaconda3/lib/python3.10/site-packages/aiohttp/client.py", line 770, in _request
    resp = await handler(req)
  File "/Users/MuhammadUsman/anaconda3/lib/python3.10/site-packages/aiohttp/client.py", line 725, in _connect_and_send_request
    conn = await self._connector.connect(
  File "/Users/MuhammadUsman/anaconda3/lib/python3.10/site-packages/aiohttp/connector.py", line 622, in connect
    proto = await self._create_connection(req, traces, timeout)
  File "/Users/MuhammadUsman/anaconda3/lib/python3.10/site-packages/aiohttp/connector.py", line 1189, in _create_connection
    _, proto = await self._create_direct_connection(req, traces, timeout)
  File "/Users/MuhammadUsman/anaconda3/lib/python3.10/site-packages/aiohttp/connector.py", line 1518, in _create_direct_connection
    raise ClientConnectorDNSError(req.connection_key, exc) from exc
aiohttp.client_exceptions.ClientConnectorDNSError: Cannot connect to host gateway-us-east1-b.discord.gg:443 ssl:default [nodename nor servname provided, or not known]
2025-07-24 22:24:50,770 ERROR: Attempting a reconnect in 0.60s
Traceback (most recent call last):
  File "/Users/MuhammadUsman/anaconda3/lib/python3.10/site-packages/aiohttp/connector.py", line 1512, in _create_direct_connection
    hosts = await self._resolve_host(host, port, traces=traces)
  File "/Users/MuhammadUsman/anaconda3/lib/python3.10/site-packages/aiohttp/connector.py", line 1128, in _resolve_host
    return await asyncio.shield(resolved_host_task)
  File "/Users/MuhammadUsman/anaconda3/lib/python3.10/site-packages/aiohttp/connector.py", line 1159, in _resolve_host_with_throttle
    addrs = await self._resolver.resolve(host, port, family=self._family)
  File "/Users/MuhammadUsman/anaconda3/lib/python3.10/site-packages/aiohttp/resolver.py", line 40, in resolve
    infos = await self._loop.getaddrinfo(
  File "/Users/MuhammadUsman/anaconda3/lib/python3.10/asyncio/base_events.py", line 863, in getaddrinfo
    return await self.run_in_executor(
  File "/Users/MuhammadUsman/anaconda3/lib/python3.10/concurrent/futures/thread.py", line 58, in run
    result = self.fn(*self.args, **self.kwargs)
  File "/Users/MuhammadUsman/anaconda3/lib/python3.10/socket.py", line 955, in getaddrinfo
    for res in _socket.getaddrinfo(host, port, family, type, proto, flags):
socket.gaierror: [Errno 8] nodename nor servname provided, or not known

The above exception was the direct cause of the following exception:

Traceback (most recent call last):
  File "/Users/MuhammadUsman/anaconda3/lib/python3.10/site-packages/discord/client.py", line 701, in connect
    self.ws = await asyncio.wait_for(coro, timeout=60.0)
  File "/Users/MuhammadUsman/anaconda3/lib/python3.10/asyncio/tasks.py", line 445, in wait_for
    return fut.result()
  File "/Users/MuhammadUsman/anaconda3/lib/python3.10/site-packages/discord/gateway.py", line 375, in from_client
    socket = await client.http.ws_connect(str(url))
  File "/Users/MuhammadUsman/anaconda3/lib/python3.10/site-packages/discord/http.py", line 554, in ws_connect
    return await self.__session.ws_connect(url, **kwargs)
  File "/Users/MuhammadUsman/anaconda3/lib/python3.10/site-packages/aiohttp/client.py", line 1061, in _ws_connect
    resp = await self.request(
  File "/Users/MuhammadUsman/anaconda3/lib/python3.10/site-packages/aiohttp/client.py", line 770, in _request
    resp = await handler(req)
  File "/Users/MuhammadUsman/anaconda3/lib/python3.10/site-packages/aiohttp/client.py", line 725, in _connect_and_send_request
    conn = await self._connector.connect(
  File "/Users/MuhammadUsman/anaconda3/lib/python3.10/site-packages/aiohttp/connector.py", line 622, in connect
    proto = await self._create_connection(req, traces, timeout)
  File "/Users/MuhammadUsman/anaconda3/lib/python3.10/site-packages/aiohttp/connector.py", line 1189, in _create_connection
    _, proto = await self._create_direct_connection(req, traces, timeout)
  File "/Users/MuhammadUsman/anaconda3/lib/python3.10/site-packages/aiohttp/connector.py", line 1518, in _create_direct_connection
    raise ClientConnectorDNSError(req.connection_key, exc) from exc
aiohttp.client_exceptions.ClientConnectorDNSError: Cannot connect to host gateway-us-east1-d.discord.gg:443 ssl:default [nodename nor servname provided, or not known]
2025-07-24 22:24:51,384 ERROR: Attempting a reconnect in 2.27s
Traceback (most recent call last):
  File "/Users/MuhammadUsman/anaconda3/lib/python3.10/site-packages/aiohttp/connector.py", line 1512, in _create_direct_connection
    hosts = await self._resolve_host(host, port, traces=traces)
  File "/Users/MuhammadUsman/anaconda3/lib/python3.10/site-packages/aiohttp/connector.py", line 1128, in _resolve_host
    return await asyncio.shield(resolved_host_task)
  File "/Users/MuhammadUsman/anaconda3/lib/python3.10/site-packages/aiohttp/connector.py", line 1159, in _resolve_host_with_throttle
    addrs = await self._resolver.resolve(host, port, family=self._family)
  File "/Users/MuhammadUsman/anaconda3/lib/python3.10/site-packages/aiohttp/resolver.py", line 40, in resolve
    infos = await self._loop.getaddrinfo(
  File "/Users/MuhammadUsman/anaconda3/lib/python3.10/asyncio/base_events.py", line 863, in getaddrinfo
    return await self.run_in_executor(
  File "/Users/MuhammadUsman/anaconda3/lib/python3.10/concurrent/futures/thread.py", line 58, in run
    result = self.fn(*self.args, **self.kwargs)
  File "/Users/MuhammadUsman/anaconda3/lib/python3.10/socket.py", line 955, in getaddrinfo
    for res in _socket.getaddrinfo(host, port, family, type, proto, flags):
socket.gaierror: [Errno 8] nodename nor servname provided, or not known

The above exception was the direct cause of the following exception:

Traceback (most recent call last):
  File "/Users/MuhammadUsman/anaconda3/lib/python3.10/site-packages/discord/client.py", line 701, in connect
    self.ws = await asyncio.wait_for(coro, timeout=60.0)
  File "/Users/MuhammadUsman/anaconda3/lib/python3.10/asyncio/tasks.py", line 445, in wait_for
    return fut.result()
  File "/Users/MuhammadUsman/anaconda3/lib/python3.10/site-packages/discord/gateway.py", line 375, in from_client
    socket = await client.http.ws_connect(str(url))
  File "/Users/MuhammadUsman/anaconda3/lib/python3.10/site-packages/discord/http.py", line 554, in ws_connect
    return await self.__session.ws_connect(url, **kwargs)
  File "/Users/MuhammadUsman/anaconda3/lib/python3.10/site-packages/aiohttp/client.py", line 1061, in _ws_connect
    resp = await self.request(
  File "/Users/MuhammadUsman/anaconda3/lib/python3.10/site-packages/aiohttp/client.py", line 770, in _request
    resp = await handler(req)
  File "/Users/MuhammadUsman/anaconda3/lib/python3.10/site-packages/aiohttp/client.py", line 725, in _connect_and_send_request
    conn = await self._connector.connect(
  File "/Users/MuhammadUsman/anaconda3/lib/python3.10/site-packages/aiohttp/connector.py", line 622, in connect
    proto = await self._create_connection(req, traces, timeout)
  File "/Users/MuhammadUsman/anaconda3/lib/python3.10/site-packages/aiohttp/connector.py", line 1189, in _create_connection
    _, proto = await self._create_direct_connection(req, traces, timeout)
  File "/Users/MuhammadUsman/anaconda3/lib/python3.10/site-packages/aiohttp/connector.py", line 1518, in _create_direct_connection
    raise ClientConnectorDNSError(req.connection_key, exc) from exc
aiohttp.client_exceptions.ClientConnectorDNSError: Cannot connect to host gateway-us-east1-d.discord.gg:443 ssl:default [nodename nor servname provided, or not known]
2025-07-24 22:24:52,447 ERROR: Attempting a reconnect in 6.93s
Traceback (most recent call last):
  File "/Users/MuhammadUsman/anaconda3/lib/python3.10/site-packages/aiohttp/connector.py", line 1512, in _create_direct_connection
    hosts = await self._resolve_host(host, port, traces=traces)
  File "/Users/MuhammadUsman/anaconda3/lib/python3.10/site-packages/aiohttp/connector.py", line 1128, in _resolve_host
    return await asyncio.shield(resolved_host_task)
  File "/Users/MuhammadUsman/anaconda3/lib/python3.10/site-packages/aiohttp/connector.py", line 1159, in _resolve_host_with_throttle
    addrs = await self._resolver.resolve(host, port, family=self._family)
  File "/Users/MuhammadUsman/anaconda3/lib/python3.10/site-packages/aiohttp/resolver.py", line 40, in resolve
    infos = await self._loop.getaddrinfo(
  File "/Users/MuhammadUsman/anaconda3/lib/python3.10/asyncio/base_events.py", line 863, in getaddrinfo
    return await self.run_in_executor(
  File "/Users/MuhammadUsman/anaconda3/lib/python3.10/concurrent/futures/thread.py", line 58, in run
    result = self.fn(*self.args, **self.kwargs)
  File "/Users/MuhammadUsman/anaconda3/lib/python3.10/socket.py", line 955, in getaddrinfo
    for res in _socket.getaddrinfo(host, port, family, type, proto, flags):
socket.gaierror: [Errno 8] nodename nor servname provided, or not known

The above exception was the direct cause of the following exception:

Traceback (most recent call last):
  File "/Users/MuhammadUsman/anaconda3/lib/python3.10/site-packages/discord/client.py", line 701, in connect
    self.ws = await asyncio.wait_for(coro, timeout=60.0)
  File "/Users/MuhammadUsman/anaconda3/lib/python3.10/asyncio/tasks.py", line 445, in wait_for
    return fut.result()
  File "/Users/MuhammadUsman/anaconda3/lib/python3.10/site-packages/discord/gateway.py", line 375, in from_client
    socket = await client.http.ws_connect(str(url))
  File "/Users/MuhammadUsman/anaconda3/lib/python3.10/site-packages/discord/http.py", line 554, in ws_connect
    return await self.__session.ws_connect(url, **kwargs)
  File "/Users/MuhammadUsman/anaconda3/lib/python3.10/site-packages/aiohttp/client.py", line 1061, in _ws_connect
    resp = await self.request(
  File "/Users/MuhammadUsman/anaconda3/lib/python3.10/site-packages/aiohttp/client.py", line 770, in _request
    resp = await handler(req)
  File "/Users/MuhammadUsman/anaconda3/lib/python3.10/site-packages/aiohttp/client.py", line 725, in _connect_and_send_request
    conn = await self._connector.connect(
  File "/Users/MuhammadUsman/anaconda3/lib/python3.10/site-packages/aiohttp/connector.py", line 622, in connect
    proto = await self._create_connection(req, traces, timeout)
  File "/Users/MuhammadUsman/anaconda3/lib/python3.10/site-packages/aiohttp/connector.py", line 1189, in _create_connection
    _, proto = await self._create_direct_connection(req, traces, timeout)
  File "/Users/MuhammadUsman/anaconda3/lib/python3.10/site-packages/aiohttp/connector.py", line 1518, in _create_direct_connection
    raise ClientConnectorDNSError(req.connection_key, exc) from exc
aiohttp.client_exceptions.ClientConnectorDNSError: Cannot connect to host gateway-us-east1-b.discord.gg:443 ssl:default [nodename nor servname provided, or not known]
2025-07-24 22:24:53,658 ERROR: Attempting a reconnect in 3.08s
Traceback (most recent call last):
  File "/Users/MuhammadUsman/anaconda3/lib/python3.10/site-packages/aiohttp/connector.py", line 1512, in _create_direct_connection
    hosts = await self._resolve_host(host, port, traces=traces)
  File "/Users/MuhammadUsman/anaconda3/lib/python3.10/site-packages/aiohttp/connector.py", line 1128, in _resolve_host
    return await asyncio.shield(resolved_host_task)
  File "/Users/MuhammadUsman/anaconda3/lib/python3.10/site-packages/aiohttp/connector.py", line 1159, in _resolve_host_with_throttle
    addrs = await self._resolver.resolve(host, port, family=self._family)
  File "/Users/MuhammadUsman/anaconda3/lib/python3.10/site-packages/aiohttp/resolver.py", line 40, in resolve
    infos = await self._loop.getaddrinfo(
  File "/Users/MuhammadUsman/anaconda3/lib/python3.10/asyncio/base_events.py", line 863, in getaddrinfo
    return await self.run_in_executor(
  File "/Users/MuhammadUsman/anaconda3/lib/python3.10/concurrent/futures/thread.py", line 58, in run
    result = self.fn(*self.args, **self.kwargs)
  File "/Users/MuhammadUsman/anaconda3/lib/python3.10/socket.py", line 955, in getaddrinfo
    for res in _socket.getaddrinfo(host, port, family, type, proto, flags):
socket.gaierror: [Errno 8] nodename nor servname provided, or not known

The above exception was the direct cause of the following exception:

Traceback (most recent call last):
  File "/Users/MuhammadUsman/anaconda3/lib/python3.10/site-packages/discord/client.py", line 701, in connect
    self.ws = await asyncio.wait_for(coro, timeout=60.0)
  File "/Users/MuhammadUsman/anaconda3/lib/python3.10/asyncio/tasks.py", line 445, in wait_for
    return fut.result()
  File "/Users/MuhammadUsman/anaconda3/lib/python3.10/site-packages/discord/gateway.py", line 375, in from_client
    socket = await client.http.ws_connect(str(url))
  File "/Users/MuhammadUsman/anaconda3/lib/python3.10/site-packages/discord/http.py", line 554, in ws_connect
    return await self.__session.ws_connect(url, **kwargs)
  File "/Users/MuhammadUsman/anaconda3/lib/python3.10/site-packages/aiohttp/client.py", line 1061, in _ws_connect
    resp = await self.request(
  File "/Users/MuhammadUsman/anaconda3/lib/python3.10/site-packages/aiohttp/client.py", line 770, in _request
    resp = await handler(req)
  File "/Users/MuhammadUsman/anaconda3/lib/python3.10/site-packages/aiohttp/client.py", line 725, in _connect_and_send_request
    conn = await self._connector.connect(
  File "/Users/MuhammadUsman/anaconda3/lib/python3.10/site-packages/aiohttp/connector.py", line 622, in connect
    proto = await self._create_connection(req, traces, timeout)
  File "/Users/MuhammadUsman/anaconda3/lib/python3.10/site-packages/aiohttp/connector.py", line 1189, in _create_connection
    _, proto = await self._create_direct_connection(req, traces, timeout)
  File "/Users/MuhammadUsman/anaconda3/lib/python3.10/site-packages/aiohttp/connector.py", line 1518, in _create_direct_connection
    raise ClientConnectorDNSError(req.connection_key, exc) from exc
aiohttp.client_exceptions.ClientConnectorDNSError: Cannot connect to host gateway-us-east1-d.discord.gg:443 ssl:default [nodename nor servname provided, or not known]
2025-07-24 22:24:56,741 ERROR: Attempting a reconnect in 11.03s
Traceback (most recent call last):
  File "/Users/MuhammadUsman/anaconda3/lib/python3.10/site-packages/aiohttp/connector.py", line 1512, in _create_direct_connection
    hosts = await self._resolve_host(host, port, traces=traces)
  File "/Users/MuhammadUsman/anaconda3/lib/python3.10/site-packages/aiohttp/connector.py", line 1128, in _resolve_host
    return await asyncio.shield(resolved_host_task)
  File "/Users/MuhammadUsman/anaconda3/lib/python3.10/site-packages/aiohttp/connector.py", line 1159, in _resolve_host_with_throttle
    addrs = await self._resolver.resolve(host, port, family=self._family)
  File "/Users/MuhammadUsman/anaconda3/lib/python3.10/site-packages/aiohttp/resolver.py", line 40, in resolve
    infos = await self._loop.getaddrinfo(
  File "/Users/MuhammadUsman/anaconda3/lib/python3.10/asyncio/base_events.py", line 863, in getaddrinfo
    return await self.run_in_executor(
  File "/Users/MuhammadUsman/anaconda3/lib/python3.10/concurrent/futures/thread.py", line 58, in run
    result = self.fn(*self.args, **self.kwargs)
  File "/Users/MuhammadUsman/anaconda3/lib/python3.10/socket.py", line 955, in getaddrinfo
    for res in _socket.getaddrinfo(host, port, family, type, proto, flags):
socket.gaierror: [Errno 8] nodename nor servname provided, or not known

The above exception was the direct cause of the following exception:

Traceback (most recent call last):
  File "/Users/MuhammadUsman/anaconda3/lib/python3.10/site-packages/discord/client.py", line 701, in connect
    self.ws = await asyncio.wait_for(coro, timeout=60.0)
  File "/Users/MuhammadUsman/anaconda3/lib/python3.10/asyncio/tasks.py", line 445, in wait_for
    return fut.result()
  File "/Users/MuhammadUsman/anaconda3/lib/python3.10/site-packages/discord/gateway.py", line 375, in from_client
    socket = await client.http.ws_connect(str(url))
  File "/Users/MuhammadUsman/anaconda3/lib/python3.10/site-packages/discord/http.py", line 554, in ws_connect
    return await self.__session.ws_connect(url, **kwargs)
  File "/Users/MuhammadUsman/anaconda3/lib/python3.10/site-packages/aiohttp/client.py", line 1061, in _ws_connect
    resp = await self.request(
  File "/Users/MuhammadUsman/anaconda3/lib/python3.10/site-packages/aiohttp/client.py", line 770, in _request
    resp = await handler(req)
  File "/Users/MuhammadUsman/anaconda3/lib/python3.10/site-packages/aiohttp/client.py", line 725, in _connect_and_send_request
    conn = await self._connector.connect(
  File "/Users/MuhammadUsman/anaconda3/lib/python3.10/site-packages/aiohttp/connector.py", line 622, in connect
    proto = await self._create_connection(req, traces, timeout)
  File "/Users/MuhammadUsman/anaconda3/lib/python3.10/site-packages/aiohttp/connector.py", line 1189, in _create_connection
    _, proto = await self._create_direct_connection(req, traces, timeout)
  File "/Users/MuhammadUsman/anaconda3/lib/python3.10/site-packages/aiohttp/connector.py", line 1518, in _create_direct_connection
    raise ClientConnectorDNSError(req.connection_key, exc) from exc
aiohttp.client_exceptions.ClientConnectorDNSError: Cannot connect to host gateway-us-east1-d.discord.gg:443 ssl:default [nodename nor servname provided, or not known]
2025-07-24 22:24:59,381 ERROR: Attempting a reconnect in 79.71s
Traceback (most recent call last):
  File "/Users/MuhammadUsman/anaconda3/lib/python3.10/site-packages/aiohttp/connector.py", line 1512, in _create_direct_connection
    hosts = await self._resolve_host(host, port, traces=traces)
  File "/Users/MuhammadUsman/anaconda3/lib/python3.10/site-packages/aiohttp/connector.py", line 1128, in _resolve_host
    return await asyncio.shield(resolved_host_task)
  File "/Users/MuhammadUsman/anaconda3/lib/python3.10/site-packages/aiohttp/connector.py", line 1159, in _resolve_host_with_throttle
    addrs = await self._resolver.resolve(host, port, family=self._family)
  File "/Users/MuhammadUsman/anaconda3/lib/python3.10/site-packages/aiohttp/resolver.py", line 40, in resolve
    infos = await self._loop.getaddrinfo(
  File "/Users/MuhammadUsman/anaconda3/lib/python3.10/asyncio/base_events.py", line 863, in getaddrinfo
    return await self.run_in_executor(
  File "/Users/MuhammadUsman/anaconda3/lib/python3.10/concurrent/futures/thread.py", line 58, in run
    result = self.fn(*self.args, **self.kwargs)
  File "/Users/MuhammadUsman/anaconda3/lib/python3.10/socket.py", line 955, in getaddrinfo
    for res in _socket.getaddrinfo(host, port, family, type, proto, flags):
socket.gaierror: [Errno 8] nodename nor servname provided, or not known

The above exception was the direct cause of the following exception:

Traceback (most recent call last):
  File "/Users/MuhammadUsman/anaconda3/lib/python3.10/site-packages/discord/client.py", line 701, in connect
    self.ws = await asyncio.wait_for(coro, timeout=60.0)
  File "/Users/MuhammadUsman/anaconda3/lib/python3.10/asyncio/tasks.py", line 445, in wait_for
    return fut.result()
  File "/Users/MuhammadUsman/anaconda3/lib/python3.10/site-packages/discord/gateway.py", line 375, in from_client
    socket = await client.http.ws_connect(str(url))
  File "/Users/MuhammadUsman/anaconda3/lib/python3.10/site-packages/discord/http.py", line 554, in ws_connect
    return await self.__session.ws_connect(url, **kwargs)
  File "/Users/MuhammadUsman/anaconda3/lib/python3.10/site-packages/aiohttp/client.py", line 1061, in _ws_connect
    resp = await self.request(
  File "/Users/MuhammadUsman/anaconda3/lib/python3.10/site-packages/aiohttp/client.py", line 770, in _request
    resp = await handler(req)
  File "/Users/MuhammadUsman/anaconda3/lib/python3.10/site-packages/aiohttp/client.py", line 725, in _connect_and_send_request
    conn = await self._connector.connect(
  File "/Users/MuhammadUsman/anaconda3/lib/python3.10/site-packages/aiohttp/connector.py", line 622, in connect
    proto = await self._create_connection(req, traces, timeout)
  File "/Users/MuhammadUsman/anaconda3/lib/python3.10/site-packages/aiohttp/connector.py", line 1189, in _create_connection
    _, proto = await self._create_direct_connection(req, traces, timeout)
  File "/Users/MuhammadUsman/anaconda3/lib/python3.10/site-packages/aiohttp/connector.py", line 1518, in _create_direct_connection
    raise ClientConnectorDNSError(req.connection_key, exc) from exc
aiohttp.client_exceptions.ClientConnectorDNSError: Cannot connect to host gateway-us-east1-b.discord.gg:443 ssl:default [nodename nor servname provided, or not known]
2025-07-24 22:25:07,777 ERROR: Attempting a reconnect in 31.17s
Traceback (most recent call last):
  File "/Users/MuhammadUsman/anaconda3/lib/python3.10/site-packages/aiohttp/connector.py", line 1512, in _create_direct_connection
    hosts = await self._resolve_host(host, port, traces=traces)
  File "/Users/MuhammadUsman/anaconda3/lib/python3.10/site-packages/aiohttp/connector.py", line 1128, in _resolve_host
    return await asyncio.shield(resolved_host_task)
  File "/Users/MuhammadUsman/anaconda3/lib/python3.10/site-packages/aiohttp/connector.py", line 1159, in _resolve_host_with_throttle
    addrs = await self._resolver.resolve(host, port, family=self._family)
  File "/Users/MuhammadUsman/anaconda3/lib/python3.10/site-packages/aiohttp/resolver.py", line 40, in resolve
    infos = await self._loop.getaddrinfo(
  File "/Users/MuhammadUsman/anaconda3/lib/python3.10/asyncio/base_events.py", line 863, in getaddrinfo
    return await self.run_in_executor(
  File "/Users/MuhammadUsman/anaconda3/lib/python3.10/concurrent/futures/thread.py", line 58, in run
    result = self.fn(*self.args, **self.kwargs)
  File "/Users/MuhammadUsman/anaconda3/lib/python3.10/socket.py", line 955, in getaddrinfo
    for res in _socket.getaddrinfo(host, port, family, type, proto, flags):
socket.gaierror: [Errno 8] nodename nor servname provided, or not known

The above exception was the direct cause of the following exception:

Traceback (most recent call last):
  File "/Users/MuhammadUsman/anaconda3/lib/python3.10/site-packages/discord/client.py", line 701, in connect
    self.ws = await asyncio.wait_for(coro, timeout=60.0)
  File "/Users/MuhammadUsman/anaconda3/lib/python3.10/asyncio/tasks.py", line 445, in wait_for
    return fut.result()
  File "/Users/MuhammadUsman/anaconda3/lib/python3.10/site-packages/discord/gateway.py", line 375, in from_client
    socket = await client.http.ws_connect(str(url))
  File "/Users/MuhammadUsman/anaconda3/lib/python3.10/site-packages/discord/http.py", line 554, in ws_connect
    return await self.__session.ws_connect(url, **kwargs)
  File "/Users/MuhammadUsman/anaconda3/lib/python3.10/site-packages/aiohttp/client.py", line 1061, in _ws_connect
    resp = await self.request(
  File "/Users/MuhammadUsman/anaconda3/lib/python3.10/site-packages/aiohttp/client.py", line 770, in _request
    resp = await handler(req)
  File "/Users/MuhammadUsman/anaconda3/lib/python3.10/site-packages/aiohttp/client.py", line 725, in _connect_and_send_request
    conn = await self._connector.connect(
  File "/Users/MuhammadUsman/anaconda3/lib/python3.10/site-packages/aiohttp/connector.py", line 622, in connect
    proto = await self._create_connection(req, traces, timeout)
  File "/Users/MuhammadUsman/anaconda3/lib/python3.10/site-packages/aiohttp/connector.py", line 1189, in _create_connection
    _, proto = await self._create_direct_connection(req, traces, timeout)
  File "/Users/MuhammadUsman/anaconda3/lib/python3.10/site-packages/aiohttp/connector.py", line 1518, in _create_direct_connection
    raise ClientConnectorDNSError(req.connection_key, exc) from exc
aiohttp.client_exceptions.ClientConnectorDNSError: Cannot connect to host gateway-us-east1-d.discord.gg:443 ssl:default [nodename nor servname provided, or not known]
2025-07-24 22:25:38,957 ERROR: Attempting a reconnect in 30.98s
Traceback (most recent call last):
  File "/Users/MuhammadUsman/anaconda3/lib/python3.10/site-packages/aiohttp/connector.py", line 1512, in _create_direct_connection
    hosts = await self._resolve_host(host, port, traces=traces)
  File "/Users/MuhammadUsman/anaconda3/lib/python3.10/site-packages/aiohttp/connector.py", line 1128, in _resolve_host
    return await asyncio.shield(resolved_host_task)
  File "/Users/MuhammadUsman/anaconda3/lib/python3.10/site-packages/aiohttp/connector.py", line 1159, in _resolve_host_with_throttle
    addrs = await self._resolver.resolve(host, port, family=self._family)
  File "/Users/MuhammadUsman/anaconda3/lib/python3.10/site-packages/aiohttp/resolver.py", line 40, in resolve
    infos = await self._loop.getaddrinfo(
  File "/Users/MuhammadUsman/anaconda3/lib/python3.10/asyncio/base_events.py", line 863, in getaddrinfo
    return await self.run_in_executor(
  File "/Users/MuhammadUsman/anaconda3/lib/python3.10/concurrent/futures/thread.py", line 58, in run
    result = self.fn(*self.args, **self.kwargs)
  File "/Users/MuhammadUsman/anaconda3/lib/python3.10/socket.py", line 955, in getaddrinfo
    for res in _socket.getaddrinfo(host, port, family, type, proto, flags):
socket.gaierror: [Errno 8] nodename nor servname provided, or not known

The above exception was the direct cause of the following exception:

Traceback (most recent call last):
  File "/Users/MuhammadUsman/anaconda3/lib/python3.10/site-packages/discord/client.py", line 701, in connect
    self.ws = await asyncio.wait_for(coro, timeout=60.0)
  File "/Users/MuhammadUsman/anaconda3/lib/python3.10/asyncio/tasks.py", line 445, in wait_for
    return fut.result()
  File "/Users/MuhammadUsman/anaconda3/lib/python3.10/site-packages/discord/gateway.py", line 375, in from_client
    socket = await client.http.ws_connect(str(url))
  File "/Users/MuhammadUsman/anaconda3/lib/python3.10/site-packages/discord/http.py", line 554, in ws_connect
    return await self.__session.ws_connect(url, **kwargs)
  File "/Users/MuhammadUsman/anaconda3/lib/python3.10/site-packages/aiohttp/client.py", line 1061, in _ws_connect
    resp = await self.request(
  File "/Users/MuhammadUsman/anaconda3/lib/python3.10/site-packages/aiohttp/client.py", line 770, in _request
    resp = await handler(req)
  File "/Users/MuhammadUsman/anaconda3/lib/python3.10/site-packages/aiohttp/client.py", line 725, in _connect_and_send_request
    conn = await self._connector.connect(
  File "/Users/MuhammadUsman/anaconda3/lib/python3.10/site-packages/aiohttp/connector.py", line 622, in connect
    proto = await self._create_connection(req, traces, timeout)
  File "/Users/MuhammadUsman/anaconda3/lib/python3.10/site-packages/aiohttp/connector.py", line 1189, in _create_connection
    _, proto = await self._create_direct_connection(req, traces, timeout)
  File "/Users/MuhammadUsman/anaconda3/lib/python3.10/site-packages/aiohttp/connector.py", line 1518, in _create_direct_connection
    raise ClientConnectorDNSError(req.connection_key, exc) from exc
aiohttp.client_exceptions.ClientConnectorDNSError: Cannot connect to host gateway-us-east1-d.discord.gg:443 ssl:default [nodename nor servname provided, or not known]
2025-07-24 22:26:09,945 ERROR: Attempting a reconnect in 89.65s
Traceback (most recent call last):
  File "/Users/MuhammadUsman/anaconda3/lib/python3.10/site-packages/aiohttp/connector.py", line 1512, in _create_direct_connection
    hosts = await self._resolve_host(host, port, traces=traces)
  File "/Users/MuhammadUsman/anaconda3/lib/python3.10/site-packages/aiohttp/connector.py", line 1128, in _resolve_host
    return await asyncio.shield(resolved_host_task)
  File "/Users/MuhammadUsman/anaconda3/lib/python3.10/site-packages/aiohttp/connector.py", line 1159, in _resolve_host_with_throttle
    addrs = await self._resolver.resolve(host, port, family=self._family)
  File "/Users/MuhammadUsman/anaconda3/lib/python3.10/site-packages/aiohttp/resolver.py", line 40, in resolve
    infos = await self._loop.getaddrinfo(
  File "/Users/MuhammadUsman/anaconda3/lib/python3.10/asyncio/base_events.py", line 863, in getaddrinfo
    return await self.run_in_executor(
  File "/Users/MuhammadUsman/anaconda3/lib/python3.10/concurrent/futures/thread.py", line 58, in run
    result = self.fn(*self.args, **self.kwargs)
  File "/Users/MuhammadUsman/anaconda3/lib/python3.10/socket.py", line 955, in getaddrinfo
    for res in _socket.getaddrinfo(host, port, family, type, proto, flags):
socket.gaierror: [Errno 8] nodename nor servname provided, or not known

The above exception was the direct cause of the following exception:

Traceback (most recent call last):
  File "/Users/MuhammadUsman/anaconda3/lib/python3.10/site-packages/discord/client.py", line 701, in connect
    self.ws = await asyncio.wait_for(coro, timeout=60.0)
  File "/Users/MuhammadUsman/anaconda3/lib/python3.10/asyncio/tasks.py", line 445, in wait_for
    return fut.result()
  File "/Users/MuhammadUsman/anaconda3/lib/python3.10/site-packages/discord/gateway.py", line 375, in from_client
    socket = await client.http.ws_connect(str(url))
  File "/Users/MuhammadUsman/anaconda3/lib/python3.10/site-packages/discord/http.py", line 554, in ws_connect
    return await self.__session.ws_connect(url, **kwargs)
  File "/Users/MuhammadUsman/anaconda3/lib/python3.10/site-packages/aiohttp/client.py", line 1061, in _ws_connect
    resp = await self.request(
  File "/Users/MuhammadUsman/anaconda3/lib/python3.10/site-packages/aiohttp/client.py", line 770, in _request
    resp = await handler(req)
  File "/Users/MuhammadUsman/anaconda3/lib/python3.10/site-packages/aiohttp/client.py", line 725, in _connect_and_send_request
    conn = await self._connector.connect(
  File "/Users/MuhammadUsman/anaconda3/lib/python3.10/site-packages/aiohttp/connector.py", line 622, in connect
    proto = await self._create_connection(req, traces, timeout)
  File "/Users/MuhammadUsman/anaconda3/lib/python3.10/site-packages/aiohttp/connector.py", line 1189, in _create_connection
    _, proto = await self._create_direct_connection(req, traces, timeout)
  File "/Users/MuhammadUsman/anaconda3/lib/python3.10/site-packages/aiohttp/connector.py", line 1518, in _create_direct_connection
    raise ClientConnectorDNSError(req.connection_key, exc) from exc
aiohttp.client_exceptions.ClientConnectorDNSError: Cannot connect to host gateway-us-east1-d.discord.gg:443 ssl:default [nodename nor servname provided, or not known]
2025-07-24 22:26:19,101 ERROR: Attempting a reconnect in 218.75s
Traceback (most recent call last):
  File "/Users/MuhammadUsman/anaconda3/lib/python3.10/site-packages/aiohttp/connector.py", line 1512, in _create_direct_connection
    hosts = await self._resolve_host(host, port, traces=traces)
  File "/Users/MuhammadUsman/anaconda3/lib/python3.10/site-packages/aiohttp/connector.py", line 1128, in _resolve_host
    return await asyncio.shield(resolved_host_task)
  File "/Users/MuhammadUsman/anaconda3/lib/python3.10/site-packages/aiohttp/connector.py", line 1159, in _resolve_host_with_throttle
    addrs = await self._resolver.resolve(host, port, family=self._family)
  File "/Users/MuhammadUsman/anaconda3/lib/python3.10/site-packages/aiohttp/resolver.py", line 40, in resolve
    infos = await self._loop.getaddrinfo(
  File "/Users/MuhammadUsman/anaconda3/lib/python3.10/asyncio/base_events.py", line 863, in getaddrinfo
    return await self.run_in_executor(
  File "/Users/MuhammadUsman/anaconda3/lib/python3.10/concurrent/futures/thread.py", line 58, in run
    result = self.fn(*self.args, **self.kwargs)
  File "/Users/MuhammadUsman/anaconda3/lib/python3.10/socket.py", line 955, in getaddrinfo
    for res in _socket.getaddrinfo(host, port, family, type, proto, flags):
socket.gaierror: [Errno 8] nodename nor servname provided, or not known

The above exception was the direct cause of the following exception:

Traceback (most recent call last):
  File "/Users/MuhammadUsman/anaconda3/lib/python3.10/site-packages/discord/client.py", line 701, in connect
    self.ws = await asyncio.wait_for(coro, timeout=60.0)
  File "/Users/MuhammadUsman/anaconda3/lib/python3.10/asyncio/tasks.py", line 445, in wait_for
    return fut.result()
  File "/Users/MuhammadUsman/anaconda3/lib/python3.10/site-packages/discord/gateway.py", line 375, in from_client
    socket = await client.http.ws_connect(str(url))
  File "/Users/MuhammadUsman/anaconda3/lib/python3.10/site-packages/discord/http.py", line 554, in ws_connect
    return await self.__session.ws_connect(url, **kwargs)
  File "/Users/MuhammadUsman/anaconda3/lib/python3.10/site-packages/aiohttp/client.py", line 1061, in _ws_connect
    resp = await self.request(
  File "/Users/MuhammadUsman/anaconda3/lib/python3.10/site-packages/aiohttp/client.py", line 770, in _request
    resp = await handler(req)
  File "/Users/MuhammadUsman/anaconda3/lib/python3.10/site-packages/aiohttp/client.py", line 725, in _connect_and_send_request
    conn = await self._connector.connect(
  File "/Users/MuhammadUsman/anaconda3/lib/python3.10/site-packages/aiohttp/connector.py", line 622, in connect
    proto = await self._create_connection(req, traces, timeout)
  File "/Users/MuhammadUsman/anaconda3/lib/python3.10/site-packages/aiohttp/connector.py", line 1189, in _create_connection
    _, proto = await self._create_direct_connection(req, traces, timeout)
  File "/Users/MuhammadUsman/anaconda3/lib/python3.10/site-packages/aiohttp/connector.py", line 1518, in _create_direct_connection
    raise ClientConnectorDNSError(req.connection_key, exc) from exc
aiohttp.client_exceptions.ClientConnectorDNSError: Cannot connect to host gateway-us-east1-b.discord.gg:443 ssl:default [nodename nor servname provided, or not known]
2025-07-24 22:27:39,597 ERROR: Attempting a reconnect in 209.06s
Traceback (most recent call last):
  File "/Users/MuhammadUsman/anaconda3/lib/python3.10/site-packages/aiohttp/connector.py", line 1512, in _create_direct_connection
    hosts = await self._resolve_host(host, port, traces=traces)
  File "/Users/MuhammadUsman/anaconda3/lib/python3.10/site-packages/aiohttp/connector.py", line 1128, in _resolve_host
    return await asyncio.shield(resolved_host_task)
  File "/Users/MuhammadUsman/anaconda3/lib/python3.10/site-packages/aiohttp/connector.py", line 1159, in _resolve_host_with_throttle
    addrs = await self._resolver.resolve(host, port, family=self._family)
  File "/Users/MuhammadUsman/anaconda3/lib/python3.10/site-packages/aiohttp/resolver.py", line 40, in resolve
    infos = await self._loop.getaddrinfo(
  File "/Users/MuhammadUsman/anaconda3/lib/python3.10/asyncio/base_events.py", line 863, in getaddrinfo
    return await self.run_in_executor(
  File "/Users/MuhammadUsman/anaconda3/lib/python3.10/concurrent/futures/thread.py", line 58, in run
    result = self.fn(*self.args, **self.kwargs)
  File "/Users/MuhammadUsman/anaconda3/lib/python3.10/socket.py", line 955, in getaddrinfo
    for res in _socket.getaddrinfo(host, port, family, type, proto, flags):
socket.gaierror: [Errno 8] nodename nor servname provided, or not known

The above exception was the direct cause of the following exception:

Traceback (most recent call last):
  File "/Users/MuhammadUsman/anaconda3/lib/python3.10/site-packages/discord/client.py", line 701, in connect
    self.ws = await asyncio.wait_for(coro, timeout=60.0)
  File "/Users/MuhammadUsman/anaconda3/lib/python3.10/asyncio/tasks.py", line 445, in wait_for
    return fut.result()
  File "/Users/MuhammadUsman/anaconda3/lib/python3.10/site-packages/discord/gateway.py", line 375, in from_client
    socket = await client.http.ws_connect(str(url))
  File "/Users/MuhammadUsman/anaconda3/lib/python3.10/site-packages/discord/http.py", line 554, in ws_connect
    return await self.__session.ws_connect(url, **kwargs)
  File "/Users/MuhammadUsman/anaconda3/lib/python3.10/site-packages/aiohttp/client.py", line 1061, in _ws_connect
    resp = await self.request(
  File "/Users/MuhammadUsman/anaconda3/lib/python3.10/site-packages/aiohttp/client.py", line 770, in _request
    resp = await handler(req)
  File "/Users/MuhammadUsman/anaconda3/lib/python3.10/site-packages/aiohttp/client.py", line 725, in _connect_and_send_request
    conn = await self._connector.connect(
  File "/Users/MuhammadUsman/anaconda3/lib/python3.10/site-packages/aiohttp/connector.py", line 622, in connect
    proto = await self._create_connection(req, traces, timeout)
  File "/Users/MuhammadUsman/anaconda3/lib/python3.10/site-packages/aiohttp/connector.py", line 1189, in _create_connection
    _, proto = await self._create_direct_connection(req, traces, timeout)
  File "/Users/MuhammadUsman/anaconda3/lib/python3.10/site-packages/aiohttp/connector.py", line 1518, in _create_direct_connection
    raise ClientConnectorDNSError(req.connection_key, exc) from exc
aiohttp.client_exceptions.ClientConnectorDNSError: Cannot connect to host gateway-us-east1-d.discord.gg:443 ssl:default [nodename nor servname provided, or not known]
2025-07-24 22:29:57,856 ERROR: Attempting a reconnect in 45.76s
Traceback (most recent call last):
  File "/Users/MuhammadUsman/anaconda3/lib/python3.10/site-packages/aiohttp/connector.py", line 1512, in _create_direct_connection
    hosts = await self._resolve_host(host, port, traces=traces)
  File "/Users/MuhammadUsman/anaconda3/lib/python3.10/site-packages/aiohttp/connector.py", line 1128, in _resolve_host
    return await asyncio.shield(resolved_host_task)
  File "/Users/MuhammadUsman/anaconda3/lib/python3.10/site-packages/aiohttp/connector.py", line 1159, in _resolve_host_with_throttle
    addrs = await self._resolver.resolve(host, port, family=self._family)
  File "/Users/MuhammadUsman/anaconda3/lib/python3.10/site-packages/aiohttp/resolver.py", line 40, in resolve
    infos = await self._loop.getaddrinfo(
  File "/Users/MuhammadUsman/anaconda3/lib/python3.10/asyncio/base_events.py", line 863, in getaddrinfo
    return await self.run_in_executor(
  File "/Users/MuhammadUsman/anaconda3/lib/python3.10/concurrent/futures/thread.py", line 58, in run
    result = self.fn(*self.args, **self.kwargs)
  File "/Users/MuhammadUsman/anaconda3/lib/python3.10/socket.py", line 955, in getaddrinfo
    for res in _socket.getaddrinfo(host, port, family, type, proto, flags):
socket.gaierror: [Errno 8] nodename nor servname provided, or not known

The above exception was the direct cause of the following exception:

Traceback (most recent call last):
  File "/Users/MuhammadUsman/anaconda3/lib/python3.10/site-packages/discord/client.py", line 701, in connect
    self.ws = await asyncio.wait_for(coro, timeout=60.0)
  File "/Users/MuhammadUsman/anaconda3/lib/python3.10/asyncio/tasks.py", line 445, in wait_for
    return fut.result()
  File "/Users/MuhammadUsman/anaconda3/lib/python3.10/site-packages/discord/gateway.py", line 375, in from_client
    socket = await client.http.ws_connect(str(url))
  File "/Users/MuhammadUsman/anaconda3/lib/python3.10/site-packages/discord/http.py", line 554, in ws_connect
    return await self.__session.ws_connect(url, **kwargs)
  File "/Users/MuhammadUsman/anaconda3/lib/python3.10/site-packages/aiohttp/client.py", line 1061, in _ws_connect
    resp = await self.request(
  File "/Users/MuhammadUsman/anaconda3/lib/python3.10/site-packages/aiohttp/client.py", line 770, in _request
    resp = await handler(req)
  File "/Users/MuhammadUsman/anaconda3/lib/python3.10/site-packages/aiohttp/client.py", line 725, in _connect_and_send_request
    conn = await self._connector.connect(
  File "/Users/MuhammadUsman/anaconda3/lib/python3.10/site-packages/aiohttp/connector.py", line 622, in connect
    proto = await self._create_connection(req, traces, timeout)
  File "/Users/MuhammadUsman/anaconda3/lib/python3.10/site-packages/aiohttp/connector.py", line 1189, in _create_connection
    _, proto = await self._create_direct_connection(req, traces, timeout)
  File "/Users/MuhammadUsman/anaconda3/lib/python3.10/site-packages/aiohttp/connector.py", line 1518, in _create_direct_connection
    raise ClientConnectorDNSError(req.connection_key, exc) from exc
aiohttp.client_exceptions.ClientConnectorDNSError: Cannot connect to host gateway-us-east1-b.discord.gg:443 ssl:default [nodename nor servname provided, or not known]
2025-07-24 22:30:58,736 INFO: Shard ID None session has been invalidated.
2025-07-24 22:31:04,870 INFO: Shard ID None has connected to Gateway (Session ID: 2a8a28bfa6f5232e109cd941c36b3acb).
2025-07-24 22:31:06,877 INFO: Bot started and ready.
2025-07-24 22:31:10,140 INFO: Shard ID None session has been invalidated.
2025-07-24 22:31:16,021 INFO: Shard ID None has connected to Gateway (Session ID: 099937965b44b8310aa07bde88f09f37).
2025-07-24 22:31:18,026 INFO: Bot started and ready.
2025-07-24 22:31:55,483 WARNING: Can't keep up, shard ID None websocket is 14.8s behind.
2025-07-24 22:36:18,738 INFO: Shard ID None has successfully RESUMED session 099937965b44b8310aa07bde88f09f37.
2025-07-24 22:52:22,790 INFO: Shard ID None has successfully RESUMED session 099937965b44b8310aa07bde88f09f37.
2025-07-24 23:30:30,942 WARNING: PyNaCl is not installed, voice will NOT be supported
2025-07-24 23:30:30,944 INFO: logging in using static token
2025-07-24 23:30:34,460 INFO: Shard ID None has connected to Gateway (Session ID: 8da3814a4799033af310b65e697525ee).
2025-07-24 23:30:36,462 INFO: Bot started and ready.
